[2025-10-09T03:02:41.148+0000] {taskinstance.py:1087} INFO - Dependencies all met for <TaskInstance: product_generator.load_products scheduled__2025-10-03T12:00:00+00:00 [queued]>
[2025-10-09T03:02:41.164+0000] {taskinstance.py:1087} INFO - Dependencies all met for <TaskInstance: product_generator.load_products scheduled__2025-10-03T12:00:00+00:00 [queued]>
[2025-10-09T03:02:41.164+0000] {taskinstance.py:1283} INFO - 
--------------------------------------------------------------------------------
[2025-10-09T03:02:41.165+0000] {taskinstance.py:1284} INFO - Starting attempt 1 of 2
[2025-10-09T03:02:41.166+0000] {taskinstance.py:1285} INFO - 
--------------------------------------------------------------------------------
[2025-10-09T03:02:41.189+0000] {taskinstance.py:1304} INFO - Executing <Task(PythonOperator): load_products> on 2025-10-03 12:00:00+00:00
[2025-10-09T03:02:41.196+0000] {standard_task_runner.py:55} INFO - Started process 2629 to run task
[2025-10-09T03:02:41.200+0000] {standard_task_runner.py:82} INFO - Running: ['airflow', 'tasks', 'run', 'product_generator', 'load_products', 'scheduled__2025-10-03T12:00:00+00:00', '--job-id', '3', '--raw', '--subdir', 'DAGS_FOLDER/product_loader_dag.py', '--cfg-path', '/tmp/tmp3vybkh60']
[2025-10-09T03:02:41.203+0000] {standard_task_runner.py:83} INFO - Job 3: Subtask load_products
[2025-10-09T03:02:41.317+0000] {task_command.py:389} INFO - Running <TaskInstance: product_generator.load_products scheduled__2025-10-03T12:00:00+00:00 [running]> on host c2751665404c
[2025-10-09T03:02:41.417+0000] {taskinstance.py:1513} INFO - Exporting the following env vars:
AIRFLOW_CTX_DAG_OWNER=airflow
AIRFLOW_CTX_DAG_ID=product_generator
AIRFLOW_CTX_TASK_ID=load_products
AIRFLOW_CTX_EXECUTION_DATE=2025-10-03T12:00:00+00:00
AIRFLOW_CTX_TRY_NUMBER=1
AIRFLOW_CTX_DAG_RUN_ID=scheduled__2025-10-03T12:00:00+00:00
[2025-10-09T03:02:41.420+0000] {logging_mixin.py:137} INFO - Schema file config/schema.json not found.
[2025-10-09T03:02:41.421+0000] {python.py:177} INFO - Done. Returned value was: None
[2025-10-09T03:02:41.433+0000] {taskinstance.py:1327} INFO - Marking task as SUCCESS. dag_id=product_generator, task_id=load_products, execution_date=20251003T120000, start_date=20251009T030241, end_date=20251009T030241
[2025-10-09T03:02:41.494+0000] {local_task_job.py:159} INFO - Task exited with return code 0
[2025-10-09T03:02:41.573+0000] {taskinstance.py:2582} INFO - 0 downstream tasks scheduled from follow-on schedule check
[2025-10-09T04:43:56.796+0000] {taskinstance.py:1087} INFO - Dependencies all met for <TaskInstance: product_generator.load_products scheduled__2025-10-03T12:00:00+00:00 [queued]>
[2025-10-09T04:43:56.809+0000] {taskinstance.py:1087} INFO - Dependencies all met for <TaskInstance: product_generator.load_products scheduled__2025-10-03T12:00:00+00:00 [queued]>
[2025-10-09T04:43:56.813+0000] {taskinstance.py:1283} INFO - 
--------------------------------------------------------------------------------
[2025-10-09T04:43:56.814+0000] {taskinstance.py:1284} INFO - Starting attempt 1 of 2
[2025-10-09T04:43:56.814+0000] {taskinstance.py:1285} INFO - 
--------------------------------------------------------------------------------
[2025-10-09T04:43:56.833+0000] {taskinstance.py:1304} INFO - Executing <Task(PythonOperator): load_products> on 2025-10-03 12:00:00+00:00
[2025-10-09T04:43:56.848+0000] {standard_task_runner.py:55} INFO - Started process 1536 to run task
[2025-10-09T04:43:56.853+0000] {standard_task_runner.py:82} INFO - Running: ['airflow', 'tasks', 'run', 'product_generator', 'load_products', 'scheduled__2025-10-03T12:00:00+00:00', '--job-id', '9', '--raw', '--subdir', 'DAGS_FOLDER/product_loader_dag.py', '--cfg-path', '/tmp/tmp7kwptgv0']
[2025-10-09T04:43:56.857+0000] {standard_task_runner.py:83} INFO - Job 9: Subtask load_products
[2025-10-09T04:43:56.982+0000] {task_command.py:389} INFO - Running <TaskInstance: product_generator.load_products scheduled__2025-10-03T12:00:00+00:00 [running]> on host 81fbc710bbce
[2025-10-09T04:43:57.083+0000] {taskinstance.py:1513} INFO - Exporting the following env vars:
AIRFLOW_CTX_DAG_OWNER=airflow
AIRFLOW_CTX_DAG_ID=product_generator
AIRFLOW_CTX_TASK_ID=load_products
AIRFLOW_CTX_EXECUTION_DATE=2025-10-03T12:00:00+00:00
AIRFLOW_CTX_TRY_NUMBER=1
AIRFLOW_CTX_DAG_RUN_ID=scheduled__2025-10-03T12:00:00+00:00
[2025-10-09T04:43:57.098+0000] {taskinstance.py:1772} ERROR - Task failed with exception
Traceback (most recent call last):
  File "/home/airflow/.local/lib/python3.7/site-packages/sqlalchemy/engine/base.py", line 3361, in _wrap_pool_connect
    return fn()
  File "/home/airflow/.local/lib/python3.7/site-packages/sqlalchemy/pool/base.py", line 325, in connect
    return _ConnectionFairy._checkout(self)
  File "/home/airflow/.local/lib/python3.7/site-packages/sqlalchemy/pool/base.py", line 888, in _checkout
    fairy = _ConnectionRecord.checkout(pool)
  File "/home/airflow/.local/lib/python3.7/site-packages/sqlalchemy/pool/base.py", line 491, in checkout
    rec = pool._do_get()
  File "/home/airflow/.local/lib/python3.7/site-packages/sqlalchemy/pool/impl.py", line 146, in _do_get
    self._dec_overflow()
  File "/home/airflow/.local/lib/python3.7/site-packages/sqlalchemy/util/langhelpers.py", line 72, in __exit__
    with_traceback=exc_tb,
  File "/home/airflow/.local/lib/python3.7/site-packages/sqlalchemy/util/compat.py", line 210, in raise_
    raise exception
  File "/home/airflow/.local/lib/python3.7/site-packages/sqlalchemy/pool/impl.py", line 143, in _do_get
    return self._create_connection()
  File "/home/airflow/.local/lib/python3.7/site-packages/sqlalchemy/pool/base.py", line 271, in _create_connection
    return _ConnectionRecord(self)
  File "/home/airflow/.local/lib/python3.7/site-packages/sqlalchemy/pool/base.py", line 386, in __init__
    self.__connect()
  File "/home/airflow/.local/lib/python3.7/site-packages/sqlalchemy/pool/base.py", line 685, in __connect
    pool.logger.debug("Error on connect(): %s", e)
  File "/home/airflow/.local/lib/python3.7/site-packages/sqlalchemy/util/langhelpers.py", line 72, in __exit__
    with_traceback=exc_tb,
  File "/home/airflow/.local/lib/python3.7/site-packages/sqlalchemy/util/compat.py", line 210, in raise_
    raise exception
  File "/home/airflow/.local/lib/python3.7/site-packages/sqlalchemy/pool/base.py", line 680, in __connect
    self.dbapi_connection = connection = pool._invoke_creator(self)
  File "/home/airflow/.local/lib/python3.7/site-packages/sqlalchemy/engine/create.py", line 578, in connect
    return dialect.connect(*cargs, **cparams)
  File "/home/airflow/.local/lib/python3.7/site-packages/sqlalchemy/engine/default.py", line 598, in connect
    return self.dbapi.connect(*cargs, **cparams)
  File "/home/airflow/.local/lib/python3.7/site-packages/psycopg2/__init__.py", line 122, in connect
    conn = _connect(dsn, connection_factory=connection_factory, **kwasync)
psycopg2.OperationalError: connection to server at "localhost" (::1), port 5434 failed: Connection refused
	Is the server running on that host and accepting TCP/IP connections?
connection to server at "localhost" (127.0.0.1), port 5434 failed: Connection refused
	Is the server running on that host and accepting TCP/IP connections?


The above exception was the direct cause of the following exception:

Traceback (most recent call last):
  File "/home/airflow/.local/lib/python3.7/site-packages/airflow/operators/python.py", line 175, in execute
    return_value = self.execute_callable()
  File "/home/airflow/.local/lib/python3.7/site-packages/airflow/operators/python.py", line 192, in execute_callable
    return self.python_callable(*self.op_args, **self.op_kwargs)
  File "/opt/airflow/scripts/main_load_products.py", line 21, in main
    cat_df = pd.read_sql("SELECT category_id, category_name FROM categories", engine)
  File "/home/airflow/.local/lib/python3.7/site-packages/pandas/io/sql.py", line 634, in read_sql
    chunksize=chunksize,
  File "/home/airflow/.local/lib/python3.7/site-packages/pandas/io/sql.py", line 1579, in read_query
    result = self.execute(*args)
  File "/home/airflow/.local/lib/python3.7/site-packages/pandas/io/sql.py", line 1424, in execute
    return self.connectable.execution_options().execute(*args, **kwargs)
  File "<string>", line 2, in execute
  File "/home/airflow/.local/lib/python3.7/site-packages/sqlalchemy/util/deprecations.py", line 402, in warned
    return fn(*args, **kwargs)
  File "/home/airflow/.local/lib/python3.7/site-packages/sqlalchemy/engine/base.py", line 3256, in execute
    connection = self.connect(close_with_result=True)
  File "/home/airflow/.local/lib/python3.7/site-packages/sqlalchemy/engine/base.py", line 3315, in connect
    return self._connection_cls(self, close_with_result=close_with_result)
  File "/home/airflow/.local/lib/python3.7/site-packages/sqlalchemy/engine/base.py", line 96, in __init__
    else engine.raw_connection()
  File "/home/airflow/.local/lib/python3.7/site-packages/sqlalchemy/engine/base.py", line 3394, in raw_connection
    return self._wrap_pool_connect(self.pool.connect, _connection)
  File "/home/airflow/.local/lib/python3.7/site-packages/sqlalchemy/engine/base.py", line 3365, in _wrap_pool_connect
    e, dialect, self
  File "/home/airflow/.local/lib/python3.7/site-packages/sqlalchemy/engine/base.py", line 2199, in _handle_dbapi_exception_noconnection
    sqlalchemy_exception, with_traceback=exc_info[2], from_=e
  File "/home/airflow/.local/lib/python3.7/site-packages/sqlalchemy/util/compat.py", line 210, in raise_
    raise exception
  File "/home/airflow/.local/lib/python3.7/site-packages/sqlalchemy/engine/base.py", line 3361, in _wrap_pool_connect
    return fn()
  File "/home/airflow/.local/lib/python3.7/site-packages/sqlalchemy/pool/base.py", line 325, in connect
    return _ConnectionFairy._checkout(self)
  File "/home/airflow/.local/lib/python3.7/site-packages/sqlalchemy/pool/base.py", line 888, in _checkout
    fairy = _ConnectionRecord.checkout(pool)
  File "/home/airflow/.local/lib/python3.7/site-packages/sqlalchemy/pool/base.py", line 491, in checkout
    rec = pool._do_get()
  File "/home/airflow/.local/lib/python3.7/site-packages/sqlalchemy/pool/impl.py", line 146, in _do_get
    self._dec_overflow()
  File "/home/airflow/.local/lib/python3.7/site-packages/sqlalchemy/util/langhelpers.py", line 72, in __exit__
    with_traceback=exc_tb,
  File "/home/airflow/.local/lib/python3.7/site-packages/sqlalchemy/util/compat.py", line 210, in raise_
    raise exception
  File "/home/airflow/.local/lib/python3.7/site-packages/sqlalchemy/pool/impl.py", line 143, in _do_get
    return self._create_connection()
  File "/home/airflow/.local/lib/python3.7/site-packages/sqlalchemy/pool/base.py", line 271, in _create_connection
    return _ConnectionRecord(self)
  File "/home/airflow/.local/lib/python3.7/site-packages/sqlalchemy/pool/base.py", line 386, in __init__
    self.__connect()
  File "/home/airflow/.local/lib/python3.7/site-packages/sqlalchemy/pool/base.py", line 685, in __connect
    pool.logger.debug("Error on connect(): %s", e)
  File "/home/airflow/.local/lib/python3.7/site-packages/sqlalchemy/util/langhelpers.py", line 72, in __exit__
    with_traceback=exc_tb,
  File "/home/airflow/.local/lib/python3.7/site-packages/sqlalchemy/util/compat.py", line 210, in raise_
    raise exception
  File "/home/airflow/.local/lib/python3.7/site-packages/sqlalchemy/pool/base.py", line 680, in __connect
    self.dbapi_connection = connection = pool._invoke_creator(self)
  File "/home/airflow/.local/lib/python3.7/site-packages/sqlalchemy/engine/create.py", line 578, in connect
    return dialect.connect(*cargs, **cparams)
  File "/home/airflow/.local/lib/python3.7/site-packages/sqlalchemy/engine/default.py", line 598, in connect
    return self.dbapi.connect(*cargs, **cparams)
  File "/home/airflow/.local/lib/python3.7/site-packages/psycopg2/__init__.py", line 122, in connect
    conn = _connect(dsn, connection_factory=connection_factory, **kwasync)
sqlalchemy.exc.OperationalError: (psycopg2.OperationalError) connection to server at "localhost" (::1), port 5434 failed: Connection refused
	Is the server running on that host and accepting TCP/IP connections?
connection to server at "localhost" (127.0.0.1), port 5434 failed: Connection refused
	Is the server running on that host and accepting TCP/IP connections?

(Background on this error at: https://sqlalche.me/e/14/e3q8)
[2025-10-09T04:43:57.128+0000] {taskinstance.py:1327} INFO - Marking task as UP_FOR_RETRY. dag_id=product_generator, task_id=load_products, execution_date=20251003T120000, start_date=20251009T044356, end_date=20251009T044357
[2025-10-09T04:43:57.150+0000] {standard_task_runner.py:105} ERROR - Failed to execute job 9 for task load_products ((psycopg2.OperationalError) connection to server at "localhost" (::1), port 5434 failed: Connection refused
	Is the server running on that host and accepting TCP/IP connections?
connection to server at "localhost" (127.0.0.1), port 5434 failed: Connection refused
	Is the server running on that host and accepting TCP/IP connections?

(Background on this error at: https://sqlalche.me/e/14/e3q8); 1536)
[2025-10-09T04:43:57.188+0000] {local_task_job.py:159} INFO - Task exited with return code 1
[2025-10-09T04:43:57.289+0000] {taskinstance.py:2582} INFO - 0 downstream tasks scheduled from follow-on schedule check
